---------------------------------------------------------------------------
AttributeError                            Traceback (most recent call last)
Cell In[121], line 332
    327     return model, test_df, test_mae
    330 if __name__ == "__main__":
    331     # Example usage (expects you already prepared dataframes):
--> 332     model, test_df_out, mae = run_pipeline(
    333 
    334     train_df, test_df, feature_cols, model_type="trans", device="cpu"
    335 
    336 )
    337     #pass

Cell In[121], line 322, in run_pipeline(train_df, test_df, feature_cols, seq_len, batch_size, model_type, device)
    320         # robust assignment (one by one)
    321         for i, p in zip(idx.tolist(), pred):
--> 322             test_df.loc[i, "pred"] = p
    324 mask = ~test_df["pred"].isna()
    325 test_mae = mean_absolute_error(test_df.loc[mask, "y_clip"], test_df.loc[mask, "pred"])

File c:\Users\rxliu\.conda\envs\project1\Lib\site-packages\pandas\core\indexing.py:818, in _LocationIndexer.__setitem__(self, key, value)
    815 self._has_valid_setitem_indexer(key)
    817 iloc = self if self.name == "iloc" else self.obj.iloc
--> 818 iloc._setitem_with_indexer(indexer, value, self.name)
...
-> 2027     if element._hasna:
   2028         raise LossySetitemError
   2029     return element

AttributeError: 'numpy.float32' object has no attribute '_hasna'
